Workbook

Sheet Template
A1: Heading
B2: Sub Heading | G2: Separation Column
C3: Sub Heading
B4: Width 0.75
D5: Particulars | E5: Constant | F5: Units | H5: Calulations->
B7: 0.0075 | D7: Width 40 | E7: 12 | F7: 12

Sheet Historical
A1: Britannia Industries Limited
A2: Historical Financial Information
H3: 2020 | I3: =H3+1 -> 2021 | J3: =I3+1 -> 2022 | K3: =J3+1 -> 2023 | L3: =K3+1 -> 2024 | M3: =L3+1 -> 2025
A4: Income Satement
D6: Revenue from operations | H6: 11443.99 | I6: 12883.04 | J6: 13944.67 | K6: 15984.9 | L6: 16546.21 | M6: 17535.02
D7: Other operating revenues | H7: 155.56 | I7: 253.1 | J7: 191.59 | K7: 315.65 | L7: 223.06 | M7: 407.65
D8: Total Revenue from operations | H8: 11599.55 | I8: 13136.14 | J8: 14136.26 | K8: 16300.55 | L8: 16769.27 | M8: 17942.67
D9: Other income | H9: 279.4 | I9: 312.87 | J9: 222.83 | K9: 215.86 | L9: 214.18 | M9: 227.09
D10: Total Income | H10: 11878.95 | I10: 13449.01 | J10: 14359.09 | K10: 16516.41 | L10: 16983.45 | M10: 18169.76
D11: Cost of materials consumed | H11: 5684.98 | I11: 6502.33 | J11: 7473.97 | K11: 8326.7 | L11: 8546.89 | M11: 9859.45
D12: Purchases of stock-in-trade | H12: 1189.92 | I12: 1160.89 | J12: 1361.59 | K12: 1337.13 | L12: 941.48 | M12: 809.35
D13: Changes in inventories of finished goods, work-in-progress and stock-in-trade | H13: 52.57 | I13: -37.12 | J13: -75.26 | K13: -72.53 | L13: 3.66 | M13: -64.75
D14: Employee benefits expense | H14: 486.69 | I14: 527.38 | J14: 542.26 | K14: 658.38 | L14: 708.7 | M14: 704.59
D15: Finance costs | H15: 76.9 | I15: 110.9 | J15: 144.29 | K15: 169.1 | L15: 164 | M15: 138.8
D16: Depreciation and amortisation expense | H16: 184.81 | I16: 197.85 | J16: 200.54 | K16: 225.96 | L16: 300.7 | M16: 313.34
D17: Other expenses | H17: 2342.21 | I17: 2473.37 | J17: 2632.31 | K17: 3219.91 | L17: 3398.46 | M17: 3446.88
... D27: Profit for the year | H27: 1393.6 | I27: 1850.59 | J27: 1515.98 | K27: 2316.32 | L27: 2134.22 | M27: 2177.86
A29: Balancesheet | H29: 2020 | I29: =H29+1 -> 2021 | J29: =I29+1 -> 2022 | K29: =J29+1 -> 2023 | L29: =K29+1 -> 2024 | M29: =L29+1 -> 2025
D30: Particulars
D31: ASSETS | X31: 2020 | Y31: 2021 | Z31: 2022 | AA31: 2023 | AB31: 2024 | AC31: 2025
D32: Non-current assets
D33: Property, plant and equipment | H33: 1716.37 | I33: 1634.3 | J33: 1584.05 | K33: 2472.19 | L33: 2602.94 | M33: 2734.61
D34: Capital work-in-progress | H34: 39.55 | I34: 116.52 | J34: 535.68 | K34: 105.08 | L34: 187.54 | M34: 89.2
D35: Investment property | H35: 14.47 | I35: 14.21 | J35: 13.95 | K35: 40.63 | L35: 27.48 | M35: 28.9
D36: Goodwill | H36: 138.97 | I36: 135.9 | J36: 139.61 | K36: 128.16 | L36: 129.82 | M36: 132.78
D37: Other intangible assets | H37: 8.37 | I37: 8.54 | J37: 15.6 | K37: 14.24 | L37: 10.9 | M37: 7.51
D38: Investment in associates and joint venture | H38: 1.48 | I38: 2.29 | J38: 2.09 | K38: 495.16 | L38: 494.36 | M38: 483.62
D39: Financial assets (Non-current):
D40: (i) Investments | H40: 1882.98 | I40: 1385.15 | J40: 926.55 | K40: 1028.09 | L40: 575.85 | M40: 1270.17
D41: (ii) Loans receivable | H41: 202.95 | I41: 74.58 | J41: 100 | K41: 150 | L41: 0 | M41: 25
D42: (iii) Other financial assets | H42: 31.33 | I42: 30.13 | J42: 31.8 | K42: 23.57 | L42: 25.5 | M42: 28.19
D43: Deferred tax assets (net) | H43: 19.56 | I43: 9.66 | J43: 51.67 | K43: 57.25 | L43: 43.88 | M43: 36.65
D44: Income-tax assets (net) | H44: 68.77 | I44: 71.84 | J44: 44.93 | K44: 43.64 | L44: 67.95 | M44: 46.26
D45: Other non-current assets | H45: 42.46 | I45: 105.98 | J45: 99.18 | K45: 48.56 | L45: 58.68 | M45: 42.04
D46: Total non-current assets | H46: 4167.26 | I46: 3589.1 | J46: 3545.11 | K46: 4564.57 | L46: 4224.9 | M46: 4924.87
D47: Current assets
D48: Inventories | H48: 740.96 | I48: 1091.49 | J48: 1367.49 | K48: 1193.18 | L48: 1181.22 | M48: 1236.51
D49: Financial assets (Current):
D50: (i) Investments | H50: 1008.77 | I50: 1393.25 | J50: 833.73 | K50: 1800.99 | L50: 1696.51 | M50: 1111.64
D51: (ii) Trade receivables | H51: 320.36 | I51: 257.27 | J51: 331.93 | K51: 328.94 | L51: 393.33 | M51: 448.61
...

Sheet Model
A1: Britannia Industries Limited | H1: Historical Period | N1: Forcasted Period
A2: Financial Statement and Analysis | F2: Units | H2: 2020 | I2: =H2+1 -> 2021 | J2: =I2+1 -> 2022 | K2: =J2+1 -> 2023 | L2: =K2+1 -> 2024 | M2: =L2+1 -> 2025 | N2: =M2+1 -> 2026 | O2: =N2+1 -> 2027 | P2: =O2+1 -> 2028 | ... S2: =R2+1 -> 2031
A4: Ratios & Assumptions
D6: Live Scenario | E6: Base Case | F6: Units
D7: Revenue(Growth) | F7: % | I7: =I26/H26-1 -> 0.13246979 | J7: =J26/I26-1 -> 0.076134999 | K7: =K26/J26-1 -> 0.15310202 | L7: =L26/K26-1 -> 0.028754858 | M7: =M26/L26-1 -> 0.069973231 | N7: {=_xlfn.XLOOKUP(E6,'Scenario Analysis'!D5:D7,'Scenario Analysis'!H5:M7)} -> 0.092086981 | O7: 0.082878283 | P7: 0.074590454 | Q7: 0.067131409 | R7: 0.060418268 | S7: 0.054376441
D8: Cost of Goood Sold (% of Revenue) | F8: % | H8: =-H27/H26 -> 0.59721886 | I8: =-I27/I26 -> 0.58054345 | J8: =-J27/J26 -> 0.61970422 | K8: =-K27/K26 -> 0.58840346 | L8: =-L27/L26 -> 0.56603716 | M8: =-M27/M26 -> 0.59099621 | N8: =AVERAGE(H8:M8) -> 0.59048389 | O8: =N8 -> 0.59048389 | P8: =O8 -> 0.59048389 | Q8: =P8 -> 0.59048389 | R8: =Q8 -> 0.59048389 | S8: =R8 -> 0.59048389
D9: Salaries and Benefits (% of Revenue) | F9: % | H9: =-H30/H26 -> 0.041957662 | I9: =-I30/I26 -> 0.040147258 | J9: =-J30/J26 -> 0.03835951 | K9: =-K30/K26 -> 0.040390048 | L9: =-L30/L26 -> 0.042261828 | M9: =-M30/M26 -> 0.039268961 | N9: =AVERAGE(H9:M9) -> 0.040397544 | O9: =N9 -> 0.040397544 | P9: =O9 -> 0.040397544 | Q9: =P9 -> 0.040397544 | R9: =Q9 -> 0.040397544 | S9: =R9 -> 0.040397544
D10: Other SG&A Expenses (% of Revenue) | F10: % | H10: =-H31/H26 -> 0.20192249 | I10: =-I31/I26 -> 0.18828743 | J10: =-J31/J26 -> 0.18620979 | K10: =-K31/K26 -> 0.19753383 | L10: =-L31/L26 -> 0.20265998 | M10: =-M31/M26 -> 0.19210519 | N10: =AVERAGE(H10:M10) -> 0.19478645 | O10: =N10 -> 0.19478645 | P10: =O10 -> 0.19478645 | Q10: =P10 -> 0.19478645 | R10: =Q10 -> 0.19478645 | S10: =R10 -> 0.19478645
D11: Depreciation and amortisation expense (% of PP&E) | F11: % | I11: =-I33/H56 -> 0.11122917 | J11: =-J33/I56 -> 0.11307138 | K11: =-K33/J56 -> 0.10513288 | L11: =-L33/K56 -> 0.11424164 | M11: =-M33/L56 -> 0.11076547 | N11: =AVERAGE(H11:M11) -> 0.11088811 | O11: =N11 -> 0.11088811 | P11: =O11 -> 0.11088811 | Q11: =P11 -> 0.11088811 | R11: =Q11 -> 0.11088811 | S11: =R11 -> 0.11088811
D12: Interest Expenses (% of Debt) | F12: % | I12: =-I35/H68 -> 0.073247251 | J12: =-J35/I68 -> 0.069131887 | K12: =-K35/J68 -> 0.068152507 | L12: =-L35/K68 -> 0.054714633 | M12: =-M35/L68 -> 0.067216798 | N12: =AVERAGE(H12:M12) -> 0.066492615 | O12: =N12 -> 0.066492615 | P12: =O12 -> 0.066492615 | Q12: =P12 -> 0.066492615 | R12: =Q12 -> 0.066492615 | S12: =R12 -> 0.066492615
D13: Other Income(Expenses) (% of Revenue) | F13: % | H13: =H39/H26 -> 0.024087141 | I13: =I39/I26 -> 0.023817499 | J13: =J39/J26 -> 0.015763009 | K13: =K39/K26 -> 0.013242498 | L13: =L39/L26 -> 0.012772172 | M13: =M39/M26 -> 0.012656422 | N13: =AVERAGE(H13:M13) -> 0.017056457 | O13: =N13 -> 0.017056457 | P13: =O13 -> 0.017056457 | Q13: =P13 -> 0.017056457 | R13: =Q13 -> 0.017056457 | S13: =R13 -> 0.017056457
D14: Taxes (% of Earnings before Tax) | F14: % | H14: =-H41/H40 -> 0.24437456 | I14: =-I41/I40 -> 0.26377203 | J14: =-J41/J40 -> 0.27059344 | K14: =-K41/K40 -> 0.23623618 | L14: =-L41/L40 -> 0.26746457 | M14: =-M41/M40 -> 0.25583191 | N14: =AVERAGE(H14:M14) -> 0.25637878 | O14: =N14 -> 0.25637878 | P14: =O14 -> 0.25637878 | Q14: =P14 -> 0.25637878 | R14: =Q14 -> 0.25637878 | S14: =R14 -> 0.25637878
D15: Dividend Payout | F15: % | H15: =-H101/H42 -> 0.31036883 | I15: =-I101/I42 -> 1.5258647 | J15: =-J101/J42 -> 1.6392543 | K15: =-K101/K42 -> 0.58681011 | L15: =-L101/L42 -> 0.81175793 | M15: =-M101/M42 -> 0.81159487 | N15: =AVERAGE(K15:M15) -> 0.73672097 | O15: =N15 -> 0.73672097 | P15: =O15 -> 0.73672097 | Q15: =P15 -> 0.73672097 | R15: =Q15 -> 0.73672097 | S15: =R15 -> 0.73672097
D16: Accounts Recievables | F16: Days | H16: =H50/H26*365 -> 10.080684 | I16: =I50/I26*365 -> 7.1484888 | J16: =J50/J26*365 -> 8.5704741 | K16: =K50/K26*365 -> 7.3655858 | L16: =L50/L26*365 -> 8.5612224 | M16: =M50/M26*365 -> 9.1258798 | N16: =AVERAGE(H16:M16) -> 8.4753892 | O16: =N16 -> 8.4753892 | P16: =O16 -> 8.4753892 | Q16: =P16 -> 8.4753892 | R16: =Q16 -> 8.4753892 | S16: =R16 -> 8.4753892
D17: Inventory DIO | F17: Days | H17: =-H52/H27*365 -> 39.040285 | I17: =-I52/I27*365 -> 52.240837 | J17: =-J52/J27*365 -> 56.976799 | K17: =-K52/K27*365 -> 45.406848 | L17: =-L52/L27*365 -> 45.421822 | M17: =-M52/M27*365 -> 42.561677 | N17: =AVERAGE(H17:M17) -> 46.941378 | O17: =N17 -> 46.941378 | P17: =O17 -> 46.941378 | Q17: =P17 -> 46.941378 | R17: =Q17 -> 46.941378 | S17: =R17 -> 46.941378
D18: Accounts Payables DPO | F18: Days | H18: =-H65/H27*365 -> 55.165161 | I18: =-I65/I27*365 -> 79.965828 | J18: =-J65/J27*365 -> 71.529634 | K18: =-K65/K27*365 -> 74.01836 | L18: =-L65/L27*365 -> 81.708676 | M18: =-M65/M27*365 -> 75.091408 | N18: =AVERAGE(H18:M18) -> 72.913178 | O18: =N18 -> 72.913178 | P18: =O18 -> 72.913178 | Q18: =P18 -> 72.913178 | R18: =Q18 -> 72.913178 | S18: =R18 -> 72.913178
D19: Capital asset turnover ratio | F19: Times | H19: =H26/H56 -> 6.5211439 | I19: =I26/I56 -> 7.4066093 | J19: =J26/J56 -> 6.5772073 | K19: =K26/K56 -> 6.1928887 | L19: =L26/L56 -> 5.927925 | M19: =M26/M56 -> 6.2731783 | N19: =AVERAGE(H19:M19) -> 6.4831587 | O19: =N19 -> 6.4831587 | P19: =O19 -> 6.4831587 | Q19: =P19 -> 6.4831587 | R19: =Q19 -> 6.4831587 | S19: =R19 -> 6.4831587
D20: Investments as % of Earnings | F20: % | H20: =H53/H42 -> 0.72385907 | I20: =I53/I42 -> 0.752868 | J20: =J53/J42 -> 0.55000462 | K20: =K53/K42 -> 0.7775221 | L20: =L53/L42 -> 0.79490868 | M20: =M53/M42 -> 0.51042767 | N20: =AVERAGE(H20:M20) -> 0.68493169 | O20: =N20 -> 0.68493169 | P20: =O20 -> 0.68493169 | Q20: =P20 -> 0.68493169 | R20: =Q20 -> 0.68493169 | S20: =R20 -> 0.68493169
D21: Income Tax as % of Cashflow from operationns | F21: % | H21: =H87/-H86 -> 0.25317188 | I21: =I87/-I86 -> 0.25476674 | J21: =J87/-J86 -> 0.31112207 | K21: =K87/-K86 -> 0.2231731 | L21: =L87/-L86 -> 0.2291505 | M21: =M87/-M86 -> 0.21742601 | N21: =AVERAGE(H21:M21) -> 0.24813505 | O21: =N21 -> 0.24813505 | P21: =O21 -> 0.24813505 | Q21: =P21 -> 0.24813505 | R21: =Q21 -> 0.24813505 | S21: =R21 -> 0.24813505
A24: Income Statement | H24: 2020 | I24: =H24+1 -> 2021 | J24: =I24+1 -> 2022 | K24: =J24+1 -> 2023 | L24: =K24+1 -> 2024 | M24: =L24+1 -> 2025 | N24: =M24+1 -> 2026 | O24: =N24+1 -> 2027 | P24: =O24+1 -> 2028 | ... S24: =R24+1 -> 2031
B25: Income
D26: Revenue | F26: ₹ in Cr | H26: =Historical!H8 -> 11599.55 | I26: =Historical!I8 -> 13136.14 | J26: =Historical!J8 -> 14136.26 | K26: =Historical!K8 -> 16300.55 | L26: =Historical!L8 -> 16769.27 | M26: =Historical!M8 -> 17942.67 | N26: =M26*(1+N7) -> 19594.956 | O26: =N26*(1+O7) -> 21218.953 | P26: =O26*(1+P7) -> 22801.684 | Q26: =P26*(1+Q7) -> 24332.393 | R26: =Q26*(1+R7) -> 25802.514 | S26: =R26*(1+S7) -> 27205.563
D27: Cost of Goood Sold(COGS) | F27: ₹ in Cr | H27: =-SUM(Historical!H11:H13) -> -6927.47 | I27: =-SUM(Historical!I11:I13) -> -7626.1 | J27: =-SUM(Historical!J11:J13) -> -8760.3 | K27: =-SUM(Historical!K11:K13) -> -9591.3 | L27: =-SUM(Historical!L11:L13) -> -9492.03 | M27: =-SUM(Historical!M11:M13) -> -10604.05 | N27: =-N26*N8 -> -11570.506 | O27: =-O26*O8 -> -12529.45 | P27: =-P26*P8 -> -13464.027 | Q27: =-Q26*Q8 -> -14367.886 | R27: =-R26*R8 -> -15235.969 | S27: =-S26*S8 -> -16064.447
D28: Gross Profit | F28: ₹ in Cr | H28: =SUM(H26:H27) -> 4672.08 | I28: =SUM(I26:I27) -> 5510.04 | J28: =SUM(J26:J27) -> 5375.96 | K28: =SUM(K26:K27) -> 6709.25 | L28: =SUM(L26:L27) -> 7277.24 | M28: =SUM(M26:M27) -> 7338.62 | N28: =SUM(N26:N27) -> 8024.4502 | O28: =SUM(O26:O27) -> 8689.5029 | ... S28: =SUM(S26:S27) -> 11141.116
C29: Expense
D30: Salalries and Benefits | F30: ₹ in Cr | H30: =-Historical!H14 -> -486.69 | I30: =-Historical!I14 -> -527.38 | J30: =-Historical!J14 -> -542.26 | K30: =-Historical!K14 -> -658.38 | L30: =-Historical!L14 -> -708.7 | M30: =-Historical!M14 -> -704.59 | N30: =-N26*N9 -> -791.58812 | O30: =-O26*O9 -> -857.19358 | P30: =-P26*P9 -> -921.13204 | Q30: =-Q26*Q9 -> -982.96893 | R30: =-R26*R9 -> -1042.3582 | S30: =-S26*S9 -> -1099.0379
D31: Other SG&A Expenses | F31: ₹ in Cr | H31: =-SUM(Historical!H17) -> -2342.21 | I31: =-SUM(Historical!I17) -> -2473.37 | J31: =-SUM(Historical!J17) -> -2632.31 | K31: =-SUM(Historical!K17) -> -3219.91 | L31: =-SUM(Historical!L17) -> -3398.46 | M31: =-SUM(Historical!M17) -> -3446.88 | N31: =N26*-N10 -> -3816.832 | O31: =O26*-O10 -> -4133.1645 | P31: =P26*-P10 -> -4441.4591 | Q31: =Q26*-Q10 -> -4739.6205 | R31: =R26*-R10 -> -5025.9802 | S31: =S26*-S10 -> -5299.2751
D32: EBITDA | F32: ₹ in Cr | H32: =SUM(H28:H31) -> 1843.18 | I32: =SUM(I28:I31) -> 2509.29 | J32: =SUM(J28:J31) -> 2201.39 | K32: =SUM(K28:K31) -> 2830.96 | L32: =SUM(L28:L31) -> 3170.08 | M32: =SUM(M28:M31) -> 3187.15 | N32: =SUM(N28:N31) -> 3416.0301 | O32: =SUM(O28:O31) -> 3699.1448 | ... S32: =SUM(S28:S31) -> 4742.8033
D33: Depriciation and Amortization Expense | F33: ₹ in Cr | H33: =-Historical!H16 -> -184.81 | I33: =-Historical!I16 -> -197.85 | J33: =-Historical!J16 -> -200.54 | K33: =-Historical!K16 -> -225.96 | L33: =-Historical!L16 -> -300.7 | M33: =-Historical!M16 -> -313.34 | N33: =N11*-M56 -> -317.16438 | O33: =O11*-N56 -> -335.15262 | P33: =P11*-O56 -> -362.92949 | Q33: =Q11*-P56 -> -390.00057 | R33: =R11*-Q56 -> -416.18186 | S33: =S11*-R56 -> -441.32684
D34: EBIT | F34: ₹ in Cr | H34: =SUM(H32:H33) -> 1658.37 | I34: =SUM(I32:I33) -> 2311.44 | J34: =SUM(J32:J33) -> 2000.85 | K34: =SUM(K32:K33) -> 2605 | L34: =SUM(L32:L33) -> 2869.38 | M34: =SUM(M32:M33) -> 2873.81 | N34: =SUM(N32:N33) -> 3098.8657 | O34: =SUM(O32:O33) -> 3363.9922 | ... S34: =SUM(S32:S33) -> 4301.4764
D35: Interest Expense | F35: ₹ in Cr | H35: =-Historical!H15 -> -76.9 | I35: =-Historical!I15 -> -110.9 | J35: =-Historical!J15 -> -144.29 | K35: =-Historical!K15 -> -169.1 | L35: =-Historical!L15 -> -164 | M35: =-Historical!M15 -> -138.8 | N35: =N12*-AVERAGE(N124,N126) -> -82.88371 | O35: =O12*-N68 -> -82.88371 | P35: =P12*-O68 -> -82.88371 | Q35: =Q12*-P68 -> -82.88371 | R35: =R12*-Q68 -> -82.88371 | S35: =S12*-R68 -> -82.88371
D36: {=Historical!D20:D22} -> Share of profit/(loss) of associates & joint venture | F36: ₹ in Cr | H36: =Historical!H20 -> 0.44 | I36: =Historical!I20 -> 0.81 | J36: =Historical!J20 -> -0.2 | K36: =Historical!K20 -> 5.41 | L36: =Historical!L20 -> -3.19 | M36: =Historical!M20 -> -10.74 | N36: =AVERAGE(K36:M36) -> -2.84 | O36: =AVERAGE(L36:N36) -> -5.59 | P36: =AVERAGE(M36:O36) -> -6.39 | Q36: =AVERAGE(N36:P36) -> -4.94 | R36: =AVERAGE(O36:Q36) -> -5.64 | S36: =AVERAGE(P36:R36) -> -5.6566667
D37: Profit before exceptional items and tax | F37: ₹ in Cr | H37: =SUM(H34:H36) -> 1581.91 | I37: =SUM(I34:I36) -> 2201.35 | J37: =SUM(J34:J36) -> 1856.36 | K37: =SUM(K34:K36) -> 2441.31 | L37: =SUM(L34:L36) -> 2702.19 | M37: =SUM(M34:M36) -> 2724.27 | N37: =SUM(N34:N36) -> 3013.142 | O37: =SUM(O34:O36) -> 3275.5185 | ... S37: =SUM(S34:S36) -> 4212.936
D38: Exceptional items | F38: ₹ in Cr | H38: =-Historical!H22 -> -17.01 | I38: =-Historical!I22 -> -0.61 | J38: =-Historical!J22 -> -0.98 | K38: =-Historical!K22 -> 375.6 | L38: =-Historical!L22 -> -2.9 | M38: =-Historical!M22 -> -24.79 | N38: 0 | O38: 0 | P38: 0 | Q38: 0 | R38: 0 | S38: 0
D39: Other Income | F39: ₹ in Cr | H39: =Historical!H9 -> 279.4 | I39: =Historical!I9 -> 312.87 | J39: =Historical!J9 -> 222.83 | K39: =Historical!K9 -> 215.86 | L39: =Historical!L9 -> 214.18 | M39: =Historical!M9 -> 227.09 | N39: =N13*N26 -> 334.22053 | O39: =O13*O26 -> 361.92015 | P39: =P13*P26 -> 388.91594 | Q39: =Q13*Q26 -> 415.02441 | R39: =R13*R26 -> 440.09947 | S39: =S13*S26 -> 464.03051
D40: Earnings Before Tax | F40: ₹ in Cr | H40: =SUM(H37:H39) -> 1844.3 | I40: =SUM(I37:I39) -> 2513.61 | J40: =SUM(J37:J39) -> 2078.21 | K40: =SUM(K37:K39) -> 3032.77 | L40: =SUM(L37:L39) -> 2913.47 | M40: =SUM(M37:M39) -> 2926.57 | N40: =SUM(N37:N39) -> 3347.3626 | O40: =SUM(O37:O39) -> 3637.4386 | ... S40: =SUM(S37:S39) -> 4676.9666
D41: Taxes | F41: ₹ in Cr | H41: =-SUM(Historical!H24:H25) -> -450.7 | I41: =-SUM(Historical!I24:I25) -> -663.02 | J41: =-SUM(Historical!J24:J25) -> -562.35 | K41: =-SUM(Historical!K24:K25) -> -716.45 | L41: =-SUM(Historical!L24:L25) -> -779.25 | M41: =-SUM(Historical!M24:M25) -> -748.71 | N41: =-(N14)*N40 -> -858.19273 | O41: =-(O14)*O40 -> -932.56209 | P41: =-(P14)*P40 -> -1002.897 | Q41: =-(Q14)*Q40 -> -1071.4371 | R41: =-(R14)*R40 -> -1136.6811 | S41: =-(S14)*S40 -> -1199.075
D42: Net Earnings | F42: ₹ in Cr | H42: =SUM(H40:H41) -> 1393.6 | I42: =SUM(I40:I41) -> 1850.59 | J42: =SUM(J40:J41) -> 1515.86 | K42: =SUM(K40:K41) -> 2316.32 | L42: =SUM(L40:L41) -> 2134.22 | M42: =SUM(M40:M41) -> 2177.86 | N42: =SUM(N40:N41) -> 2489.1698 | O42: =SUM(O40:O41) -> 2704.8766 | ... S42: =SUM(S40:S41) -> 3477.8916
A44: Balancesheet
B46: Assets
...

Sheet Scenario Analysis
A1: Britannia Industries Limited
A2: Scenarios
C4: Scenarios | E4: Growth | H4: 2026 | I4: =H4+1 -> 2027 | J4: =I4+1 -> 2028 | K4: =J4+1 -> 2029 | L4: =K4+1 -> 2030 | M4: =L4+1 -> 2031
D5: Base Case | E5: =AVERAGE(Model!I7:M7) -> 0.092086981 | H5: {=E5:E7} -> 0.092086981 | I5: =H5*(1-$E$8) -> 0.082878283 | J5: =I5*(1-$E$8) -> 0.074590454 | K5: =J5*(1-$E$8) -> 0.067131409 | L5: =K5*(1-$E$8) -> 0.060418268 | M5: =L5*(1-$E$8) -> 0.054376441
D6: Bull Case | E6: =MAX(Model!H7:M7) -> 0.15310202 | H6: 0.15310202 | I6: =H6*(1-$E$8) -> 0.13779182 | J6: =I6*(1-$E$8) -> 0.12401264 | K6: =J6*(1-$E$8) -> 0.11161137 | L6: =K6*(1-$E$8) -> 0.10045024 | M6: =L6*(1-$E$8) -> 0.090405213
D7: Bear Case | E7: 0.05 | H7: 0.05 | I7: =H7*(1-$E$8) -> 0.045 | J7: =I7*(1-$E$8) -> 0.0405 | K7: =J7*(1-$E$8) -> 0.03645 | L7: =K7*(1-$E$8) -> 0.032805 | M7: =L7*(1-$E$8) -> 0.0295245
D8: Annual Growth Tapering | E8: 0.1

Sheet Comp Data
B2: S.No. | C2: Name | D2: CMP Rs. | E2: P/E | F2: Mar Cap Rs.Cr. | G2: Qtr Profit Var % | H2: Sales Qtr Rs.Cr. | I2: ROCE % | J2: EV / EBITDA | K2: No. Eq. Shares Cr. | L2: No. Eq. Shares PY Cr. | M2: Debt Rs.Cr. | N2: Debt / Eq | O2: EV Rs.Cr. | P2: CMP / FCF | Q2: EBIDT Ann Rs.Cr. | R2: PAT 12M Rs.Cr. | S2: Levered Beta | T2: Sales | U2: Earnings
B3: 1 | C3: Nestle India | D3: 1484.4 | E3: 82.98 | F3: 286238.95 | G3: 28.84 | H3: 6747.79 | I3: 84.21 | J3: 53.37 | K3: 192.83 | L3: 192.83 | M3: 444.16 | N3: 0.08 | O3: 285342.24 | P3: 115.27 | Q3: 5346.41 | R3: 3451.73 | S3: 0.51 | T3: 23154.6 | U3: 3451.73
B4: =B3+1 -> 2 | C4: Britannia Inds. | D4: 5517.8 | E4: 52.44 | F4: 132906.25 | G4: 21.14 | H4: 4718.92 | I4: 56.02 | J4: 35.83 | K4: 24.09 | L4: 24.09 | M4: 1380.28 | N4: 0.27 | O4: 133934.09 | P4: 60.39 | Q4: 3738.37 | R4: 2533.49 | S4: 0.435 | T4: 19151.59 | U4: 2537.01
B5: =B4+1 -> 3 | C5: Bikaji Foods | D5: 673.3 | E5: 67.61 | F5: 16882.09 | G5: 117.64 | H5: 790.01 | I5: 18.16 | J5: 38.37 | K5: 25.07 | L5: 25.04 | M5: 309.73 | N5: 0.21 | O5: 16905.77 | P5: 183.18 | Q5: 362.52 | R5: 249.6 | S5: 1.122 | T5: 2883.95 | U5: 249.6
B6: =B5+1 -> 4 | C6: Zydus Wellness | D6: 517 | E6: 68.37 | F6: 16448.97 | G6: -643.12 | H6: 964.9 | I6: 6.16 | J6: 44.47 | K6: 31.82 | L6: 31.82 | M6: 3042 | N6: 0.53 | O6: 19369.47 | P6: 84.8 | Q6: 383.8 | R6: 240.42 | S6: 0.706 | T6: 3389 | U6: 240
B7: =B6+1 -> 5 | C7: Gopal Snacks | D7: 333.05 | E7: 117.24 | F7: 4150.55 | G7: 190.04 | H7: 400.76 | I7: 16.31 | J7: 56.75 | K7: 12.46 | L7: 12.46 | M7: 64.92 | N7: 0.15 | O7: 4214.55 | P7: 104.32 | Q7: 108.98 | R7: 35.4 | S7: 0.76 | T7: 1416.08 | U7: 35.4
B8: =B7+1 -> 6 | C8: Hind. Unilever | D8: 2286.2 | E8: 49.19 | F8: 537163.66 | G8: 8.62 | H8: 16351 | I8: 28.42 | J8: 33.91 | K8: 234.96 | L8: 234.96 | M8: 1478 | N8: 0.03 | O8: 535393.66 | P8: 46.98 | Q8: 15790 | R8: 10927.02 | S8: 0.514 | T8: 64468 | U8: 10927.02
B9: =B8+1 -> 7 | C9: ITC | D9: 307.5 | E9: 18.79 | F9: 385281.07 | G9: 9.62 | H9: 20047.3 | I9: 36.79 | J9: 12.84 | K9: 1252.95 | L9: 1248.47 | M9: 362.97 | N9: 0.01 | O9: 381597.68 | P9: 25.44 | Q9: 28479.56 | R9: 20630 | S9: 0.572 | T9: 79808.72 | U9: 20630
B10: =B9+1 -> 8 | C10: Marico | D10: 831 | E10: 61.27 | F10: 107876.16 | G10: 13.99 | H10: 3333 | I10: 47.21 | J10: 42.63 | K10: 129.81 | L10: 129.55 | M10: 557 | N10: 0.13 | O10: 107940.16 | P10: 76.91 | Q10: 2532 | R10: 1762 | S10: 0.458 | T10: 13611 | U10: 1762
B11: =B10+1 -> 9 | C11: Patanjali Foods | D11: 459.5 | E11: 29.75 | F11: 49998.38 | G11: 68.21 | H11: 10483.71 | I11: 15.55 | J11: 25.67 | K11: 108.81 | L11: 108.6 | M11: 2895.22 | N11: 0.24 | O11: 51294.27 | P11: 113.87 | Q11: 2088.81 | R11: 1679.58 | S11: 1.14 | T11: 38718 | U11: 1679.58

Sheet Comps
A1: Britannia Industries Limited
A2: Comps Valuation
H5: Market Data | O5: Financial Data | S5: Valuation Metrics
H6: Price | I6: Shares | J6: Market Cap | K6: Debt | L6: Cash | M6: EV | O6: Sale | P6: EBITDA | Q6: Earnings | S6: EV/Sales | T6: EV/EBITDA | U6: P/E
D7: Company Name | H7: ₹/share | I7: in Cr | J7: ₹ Cr | K7: ₹ Cr | L7: ₹ Cr | M7: ₹ Cr | O7: ₹ Cr | P7: ₹ Cr | Q7: ₹ Cr | S7: x | T7: x | U7: x
D8: {='Comp Data'!C3:C11} -> Nestle India | H8: ='Comp Data'!D3 -> 1484.4 | I8: ='Comp Data'!K3 -> 192.83 | J8: =H8*I8 -> 286236.85 | K8: ='Comp Data'!M3 -> 444.16 | L8: ='Comp Data'!P3 -> 115.27 | M8: ='Comp Data'!O3 -> 285342.24 | O8: ='Comp Data'!T3 -> 23154.6 | P8: ='Comp Data'!Q3 -> 5346.41 | Q8: {='Comp Data'!U3:U11} -> 3451.73 | S8: =M8/O8 -> 12.32335 | T8: =M8/P8 -> 53.370811 | U8: =J8/Q8 -> 82.92562
D9: Britannia Inds. | H9: ='Comp Data'!D4 -> 5517.8 | I9: ='Comp Data'!K4 -> 24.09 | J9: =H9*I9 -> 132923.8 | K9: ='Comp Data'!M4 -> 1380.28 | L9: ='Comp Data'!P4 -> 60.39 | M9: ='Comp Data'!O4 -> 133934.09 | O9: ='Comp Data'!T4 -> 19151.59 | P9: ='Comp Data'!Q4 -> 3738.37 | Q9: 2537.01 | S9: =M9/O9 -> 6.9933666 | T9: =M9/P9 -> 35.826868 | U9: =J9/Q9 -> 52.393882
D10: Bikaji Foods | H10: ='Comp Data'!D5 -> 673.3 | I10: ='Comp Data'!K5 -> 25.07 | J10: =H10*I10 -> 16879.631 | K10: ='Comp Data'!M5 -> 309.73 | L10: ='Comp Data'!P5 -> 183.18 | M10: ='Comp Data'!O5 -> 16905.77 | O10: ='Comp Data'!T5 -> 2883.95 | P10: ='Comp Data'!Q5 -> 362.52 | Q10: 249.6 | S10: =M10/O10 -> 5.8620191 | T10: =M10/P10 -> 46.634034 | U10: =J10/Q10 -> 67.626727
D11: Zydus Wellness | H11: ='Comp Data'!D6 -> 517 | I11: ='Comp Data'!K6 -> 31.82 | J11: =H11*I11 -> 16450.94 | K11: ='Comp Data'!M6 -> 3042 | L11: ='Comp Data'!P6 -> 84.8 | M11: ='Comp Data'!O6 -> 19369.47 | O11: ='Comp Data'!T6 -> 3389 | P11: ='Comp Data'!Q6 -> 383.8 | Q11: 240 | S11: =M11/O11 -> 5.7153939 | T11: =M11/P11 -> 50.467613 | U11: =J11/Q11 -> 68.545583
D12: Gopal Snacks | H12: ='Comp Data'!D7 -> 333.05 | I12: ='Comp Data'!K7 -> 12.46 | J12: =H12*I12 -> 4149.803 | K12: ='Comp Data'!M7 -> 64.92 | L12: ='Comp Data'!P7 -> 104.32 | M12: ='Comp Data'!O7 -> 4214.55 | O12: ='Comp Data'!T7 -> 1416.08 | P12: ='Comp Data'!Q7 -> 108.98 | Q12: 35.4 | S12: =M12/O12 -> 2.976209 | T12: =M12/P12 -> 38.672692 | U12: =J12/Q12 -> 117.22607
D13: Hind. Unilever | H13: ='Comp Data'!D8 -> 2286.2 | I13: ='Comp Data'!K8 -> 234.96 | J13: =H13*I13 -> 537165.55 | K13: ='Comp Data'!M8 -> 1478 | L13: ='Comp Data'!P8 -> 46.98 | M13: ='Comp Data'!O8 -> 535393.66 | O13: ='Comp Data'!T8 -> 64468 | P13: ='Comp Data'!Q8 -> 15790 | Q13: 10927.02 | S13: =M13/O13 -> 8.3047971 | T13: =M13/P13 -> 33.907135 | U13: =J13/Q13 -> 49.159382
D14: ITC | H14: ='Comp Data'!D9 -> 307.5 | I14: ='Comp Data'!K9 -> 1252.95 | J14: =H14*I14 -> 385282.12 | K14: ='Comp Data'!M9 -> 362.97 | L14: ='Comp Data'!P9 -> 25.44 | M14: ='Comp Data'!O9 -> 381597.68 | O14: ='Comp Data'!T9 -> 79808.72 | P14: ='Comp Data'!Q9 -> 28479.56 | Q14: 20630 | S14: =M14/O14 -> 4.7814033 | T14: =M14/P14 -> 13.399002 | U14: =J14/Q14 -> 18.675818
D15: Marico | H15: ='Comp Data'!D10 -> 831 | I15: ='Comp Data'!K10 -> 129.81 | J15: =H15*I15 -> 107872.11 | K15: ='Comp Data'!M10 -> 557 | L15: ='Comp Data'!P10 -> 76.91 | M15: ='Comp Data'!O10 -> 107940.16 | O15: ='Comp Data'!T10 -> 13611 | P15: ='Comp Data'!Q10 -> 2532 | Q15: 1762 | S15: =M15/O15 -> 7.9303622 | T15: =M15/P15 -> 42.630395 | U15: =J15/Q15 -> 61.221402
D16: Patanjali Foods | H16: ='Comp Data'!D11 -> 459.5 | I16: ='Comp Data'!K11 -> 108.81 | J16: =H16*I16 -> 49998.195 | K16: ='Comp Data'!M11 -> 2895.22 | L16: ='Comp Data'!P11 -> 113.87 | M16: ='Comp Data'!O11 -> 51294.27 | O16: ='Comp Data'!T11 -> 38718 | P16: ='Comp Data'!Q11 -> 2088.81 | Q16: 1679.58 | S16: =M16/O16 -> 1.3248171 | T16: =M16/P16 -> 24.556695 | U16: =J16/Q16 -> 29.768272
D18: Average | S18: =AVERAGE(S8:S15) -> 6.8608627 | T18: =AVERAGE(T8:T15) -> 39.363569 | U18: =AVERAGE(U8:U15) -> 64.721811
D19: Median | S19: =MEDIAN(S8:S15) -> 6.4276929 | T19: =MEDIAN(T8:T15) -> 40.651544 | U19: =MEDIAN(U8:U15) -> 64.424064
D21: =D9 -> Britannia Inds. | H21: {=H9:M9} -> 5517.8 | I21: 24.09 | J21: 132923.8 | K21: 1380.28 | L21: 60.39 | M21: 133934.09 | O21: {=O9:Q9} -> 19151.59 | P21: 3738.37 | Q21: 2537.01 | S21: =S9 -> 6.9933666 | T21: =T9 -> 35.826868 | U21: =U9 -> 52.393882
D23: Metric | E23: Comps | H23: EV | I23: Net Debt | J23: Equity Value | K23: Shares | L23: Share Price
D24: {=TRANSPOSE(S6:U6)} -> EV/Sales | E24: {=TRANSPOSE(S18:U18)} -> 6.8608627 | H24: =E24*O21 -> 131396.43 | I24: =K21-L21 -> 1319.89 | J24: =H24-I24 -> 130076.54 | K24: =I21 -> 24.09 | L24: =J24/K24 -> 5399.6073
D25: EV/EBITDA | E25: 39.363569 | H25: =E25*P21 -> 147155.59 | I25: =I24 -> 1319.89 | J25: =H25-I25 -> 145835.7 | K25: =K24 -> 24.09 | L25: =J25/K25 -> 6053.7856
D26: P/E | E26: 64.721811 | H26: =SUM(I26:J26) -> 165519.77 | I26: =I25 -> 1319.89 | J26: =E26*Q21 -> 164199.88 | K26: =K25 -> 24.09 | L26: =J26/K26 -> 6816.1014

Sheet WACC
A1: Britannia Industries Ltd.
A2: Weigthed Average Cost of Capital
A5: Comparable Companies Beta
H6: Equity | I6: Total | J6: Debt/ | K6: Debt/ | L6: Tax | M6: Levered | N6: Unlevered
D7: Name | H7: Value | I7: Debt | J7: Equity | K7: Capital | L7: Rate% | M7: Beta | N7: Beta
D8: ='Comp Data'!C3 -> Nestle India | H8: =Comps!J8 -> 286236.85 | I8: =Comps!K8 -> 444.16 | J8: =I8/H8 -> 0.0015517219 | K8: =I8/(I8+H8) -> 0.0015493178 | L8: 0.25 | M8: ='Comp Data'!S3 -> 0.51 | N8: =M8/(J8*(1-L8)+1) -> 0.50940716
D9: ='Comp Data'!C4 -> Britannia Inds. | H9: =Comps!J9 -> 132923.8 | I9: =Comps!K9 -> 1380.28 | J9: =I9/H9 -> 0.010383994 | K9: =I9/(I9+H9) -> 0.010277275 | L9: 0.25 | M9: =Beta!I11 -> 0.4658 | N9: =M9/(J9*(1-L9)+1) -> 0.46220039
D10: ='Comp Data'!C5 -> Bikaji Foods | H10: =Comps!J10 -> 16879.631 | I10: =Comps!K10 -> 309.73 | J10: =I10/H10 -> 0.018349335 | K10: =I10/(I10+H10) -> 0.018018704 | L10: 0.25 | M10: ='Comp Data'!S5 -> 1.122 | N10: =M10/(J10*(1-L10)+1) -> 1.1067686
D11: ='Comp Data'!C6 -> Zydus Wellness | H11: =Comps!J11 -> 16450.94 | I11: =Comps!K11 -> 3042 | J11: =I11/H11 -> 0.18491345 | K11: =I11/(I11+H11) -> 0.1560565 | L11: 0.25 | M11: ='Comp Data'!S6 -> 0.706 | N11: =M11/(J11*(1-L11)+1) -> 0.62001339
D12: ='Comp Data'!C7 -> Gopal Snacks | H12: =Comps!J12 -> 4149.803 | I12: =Comps!K12 -> 64.92 | J12: =I12/H12 -> 0.015644116 | K12: =I12/(I12+H12) -> 0.015403147 | L12: 0.25 | M12: ='Comp Data'!S7 -> 0.76 | N12: =M12/(J12*(1-L12)+1) -> 0.75118627
D13: ='Comp Data'!C8 -> Hind. Unilever | H13: =Comps!J13 -> 537165.55 | I13: =Comps!K13 -> 1478 | J13: =I13/H13 -> 0.0027514795 | K13: =I13/(I13+H13) -> 0.0027439296 | L13: 0.25 | M13: ='Comp Data'!S8 -> 0.514 | N13: =M13/(J13*(1-L13)+1) -> 0.51294149
D14: ='Comp Data'!C9 -> ITC | H14: =Comps!J14 -> 385282.12 | I14: =Comps!K14 -> 362.97 | J14: =I14/H14 -> 0.00094208887 | K14: =I14/(I14+H14) -> 0.00094120217 | L14: 0.25 | M14: ='Comp Data'!S9 -> 0.572 | N14: =M14/(J14*(1-L14)+1) -> 0.57159613
D15: ='Comp Data'!C10 -> Marico | H15: =Comps!J15 -> 107872.11 | I15: =Comps!K15 -> 557 | J15: =I15/H15 -> 0.0051635219 | K15: =I15/(I15+H15) -> 0.0051369969 | L15: 0.25 | M15: ='Comp Data'!S10 -> 0.458 | N15: =M15/(J15*(1-L15)+1) -> 0.45623317
D16: ='Comp Data'!C11 -> Patanjali Foods | H16: =Comps!J16 -> 49998.195 | I16: =Comps!K16 -> 2895.22 | J16: =I16/H16 -> 0.05790649 | K16: =I16/(I16+H16) -> 0.05473687 | L16: 0.25 | M16: ='Comp Data'!S11 -> 1.14 | N16: =M16/(J16*(1-L16)+1) -> 1.0925507
D18: Average | H18: =AVERAGE(_xlfn.ANCHORARRAY(H8)) -> 286236.85 | I18: =AVERAGE(I8:I15) -> 954.8825 | J18: =AVERAGE(J8:J15) -> 0.029962463 | K18: =AVERAGE(K8:K15) -> 0.026265884 | L18: =AVERAGE(L8:L16) -> 0.25 | M18: 0.65224175 | N18: 0.54925621
D19: Median | H19: =MEDIAN(_xlfn.ANCHORARRAY(H8)) -> 286236.85 | I19: =MEDIAN(I8:I15) -> 500.58 | J19: =MEDIAN(J8:J15) -> 0.0077737581 | K19: =MEDIAN(K8:K15) -> 0.007707136 | L19: =MEDIAN(L8:L15) -> 0.25 | M19: 0.57148874 | N19: 0.48125368
D21: =A1 -> Britannia Industries Ltd. | H21: =H9 -> 132923.8 | I21: =I9 -> 1380.28 | J21: =J9 -> 0.010383994 | K21: =K9 -> 0.010277275 | L21: =L9 -> 0.25
A23: WACC Calculation
C25: Target Capital Structure
D27: Proportion of Debt | H27: =K19 -> 0.007707136
D28: Proportion Of Equity | H28: =1-H27 -> 0.99229286
C30: Current Capital Structure
D31: Market Cap | H31: =H21 -> 132923.8
D32: Total Debt | H32: =I21 -> 1380.28
D33: Debt/ Equity | H33: =J21 -> 0.010383994
C35: Cost of Debt
D36: Pre Tax Cost of Debt | H36: =Model!N12 -> 0.066492615
D37: Tax Rate | H37: =Model!N14 -> 0.25637878
D38: After Tax Cost of Debt | H38: =H36*(1-H37) -> 0.04944532
C40: Cost of Equity
D41: Risk Free Rate | H41: 0.0703
D42: Equity Market Return | H42: ='Market Data'!H9 -> 0.11358055
D43: Equity Risk Premium | H43: =H42-H41 -> 0.043280548
D44: Levered Equity Beta | H44: =N19*(1+H33*(1-H37)) -> 0.4849698
D45: Cost of Equity | H45: =H41+H43*H44 -> 0.091289759
D47: WACC | H47: =(H45*H28)+(H38*H27) -> 0.090967258

Sheet Beta
A1: Britannia Industries Limited
A2: Company Beta(Regression)
A3: Date | B3: Britannia Price | C3: Nifty Price | D3: Britannia Return | E3: Nifty Return
A4: 44333 | B4: 3223.5239 | C4: 15175.3 | D4: -0.018763694 | E4: 0.033894726
A5: 44340 | B5: 3211.9836 | C5: 15435.65 | D5: -0.003580021 | E5: 0.017156207
A6: 44347 | B6: 3285.9214 | C6: 15670.25 | D6: 0.02301934 | E6: 0.015198557
A7: 44354 | B7: 3350.5227 | C7: 15799.35 | D7: 0.019660032 | E7: 0.0082385163
A8: 44361 | B8: 3408.25 | C8: 15683.35 | D8: 0.01722934 | E8: -0.0073420744
A9: 44368 | B9: 3456.1362 | C9: 15860.35 | D9: 0.014050093 | E9: 0.011285854
A10: 44375 | B10: 3338.6572 | C10: 15722.2 | D10: -0.033991427 | E10: -0.0087103637
A11: 44382 | B11: 3273.3496 | C11: 15689.8 | D11: -0.019561043 | E11: -0.0020608051 | H11: Beta | I11: =M31 -> 0.4658
A12: 44389 | B12: 3240.4365 | C12: 15923.4 | D12: -0.010054864 | E12: 0.014888691 | H12: Rsquare | I12: =M17 -> 0.103
A13: 44396 | B13: 3239.3066 | C13: 15856.05 | D13: -0.00034868229 | E13: -0.004229661 | L13: SUMMARY OUTPUT
A14: 44403 | B14: 3223.8623 | C14: 15763.05 | D14: -0.0047677907 | E14: -0.0058652692
A15: 44410 | B15: 3393.936 | C15: 16238.2 | D15: 0.052754651 | E15: 0.030143303 | L15: Regression Statistics
A16: 44417 | B16: 3370.9111 | C16: 16529.1 | D16: -0.0067841297 | E16: 0.017914511 | L16: Multiple R | M16: 0.321
A17: 44424 | B17: 3668.8689 | C17: 16450.5 | D17: 0.088390869 | E17: -0.0047552263 | L17: R Square | M17: 0.103
A18: 44431 | B18: 3711.8113 | C18: 16705.199 | D18: 0.011704529 | E18: 0.015482765 | L18: Adjusted R Square | M18: 0.1
A19: 44438 | B19: 3883.8157 | C19: 17323.6 | D19: 0.046339747 | E19: 0.037018439 | L19: Standard Error | M19: 0.0243
A20: 44445 | B20: 3833.5278 | C20: 17369.25 | D20: -0.012948051 | E20: 0.0026351562 | L20: Observations | M20: 279
A21: 44452 | B21: 3815.6824 | C21: 17585.15 | D21: -0.0046551009 | E21: 0.012430035
A22: 44459 | B22: 3807.2537 | C22: 17853.199 | D22: -0.0022089656 | E22: 0.015242908 | L22: ANOVA
A23: 44466 | B23: 3692.5532 | C23: 17532.051 | D23: -0.030126818 | E23: -0.017988285 | M23: df | N23: SS | O23: MS | P23: F | Q23: Significance F
A24: 44473 | B24: 3656.9565 | C24: 17895.199 | D24: -0.0096401264 | E24: 0.020713403 | L24: Regression | M24: 1 | N24: 0.0188 | O24: 0.0188 | P24: 31.91 | Q24: 4.01e-08
A25: 44480 | B25: 3667.8335 | C25: 18338.551 | D25: 0.0029743184 | E25: 0.024774888 | L25: Residual | M25: 277 | N25: 0.1632 | O25: 0.000589
A26: 44487 | B26: 3474.9231 | C26: 18114.9 | D26: -0.05259519 | E26: -0.012195641 | L26: Total | M26: 278 | N26: 0.182
A27: 44494 | B27: 3461.5039 | C27: 17671.65 | D27: -0.0038617227 | E27: -0.024468807
A28: 44501 | B28: 3418.2793 | C28: 17916.801 | D28: -0.012487234 | E28: 0.013872524
A29: 44508 | B29: 3472.9927 | C29: 18102.75 | D29: 0.016006117 | E29: 0.010378483 | M29: Coefficients | N29: Standard Error | O29: t Stat | P29: P-value | Q29: Lower 95% | R29: Upper 95%
A30: 44515 | B30: 3363.4246 | C30: 17764.801 | D30: -0.031548617 | E30: -0.018668391 | L30: Intercept | M30: 0.0012 | N30: 0.002 | O30: 0.78 | P30: 0.436 | Q30: -0.002 | R30: 0.004
A31: 44522 | B31: 3348.0742 | C31: 17026.449 | D31: -0.0045639025 | E31: -0.041562614 | L31: Market Beta | M31: 0.4658 | N31: 0.082 | O31: 5.649 | P31: 0 | Q31: 0.303 | R31: 0.628
A32: 44529 | B32: 3346.615 | C32: 17196.699 | D32: -0.00043584115 | E32: 0.0099991488
A33: 44536 | B33: 3420.7278 | C33: 17511.301 | D33: 0.022145599 | E33: 0.018294299
A34: 44543 | B34: 3330.0403 | C34: 16985.199 | D34: -0.026511171 | E34: -0.030043546
A35: 44550 | B35: 3334.8904 | C35: 17003.75 | D35: 0.0014564682 | E35: 0.0010921733
A36: 44557 | B36: 3395.8196 | C36: 17354.051 | D36: 0.018270225 | E36: 0.020601384
A37: 44564 | B37: 3519.5137 | C37: 17812.699 | D37: 0.036425402 | E37: 0.026428898
A38: 44571 | B38: 3495.688 | C38: 18255.75 | D38: -0.0067695954 | E38: 0.024872748
A39: 44578 | B39: 3407.4023 | C39: 17617.15 | D39: -0.025255585 | E39: -0.034980738
A40: 44585 | B40: 3305.0852 | C40: 17101.949 | D40: -0.030027901 | E40: -0.029244297
...

Sheet Market Data
A1: Britannia Industries Limited
A2: Market Return
A3: Date | B3: Britannia Price | C3: Nifty Price | D3: Britannia Return | E3: Nifty Return
A4: 44333 | B4: 3223.5239 | C4: 15175.3 | D4: -0.018763694 | E4: 0.033894726
A5: 44340 | B5: 3211.9836 | C5: 15435.65 | D5: -0.003580021 | E5: 0.017156207
A6: 44347 | B6: 3285.9214 | C6: 15670.25 | D6: 0.02301934 | E6: 0.015198557
A7: 44354 | B7: 3350.5227 | C7: 15799.35 | D7: 0.019660032 | E7: 0.0082385163 | G7: No. of Years | H7: 5
A8: 44361 | B8: 3408.25 | C8: 15683.35 | D8: 0.01722934 | E8: -0.0073420744 | G8: Index | H8: Nifty 50
A9: 44368 | B9: 3456.1362 | C9: 15860.35 | D9: 0.014050093 | E9: 0.011285854 | G9: Market Return | H9: =_xlfn.RRI(H7,B4,B263) -> 0.11358055
A10: 44375 | B10: 3338.6572 | C10: 15722.2 | D10: -0.033991427 | E10: -0.0087103637 | G10: Levered Beta | H10: =SLOPE(D4:D263,E4:E263) -> 0.52392004
A11: 44382 | B11: 3273.3496 | C11: 15689.8 | D11: -0.019561043 | E11: -0.0020608051
A12: 44389 | B12: 3240.4365 | C12: 15923.4 | D12: -0.010054864 | E12: 0.014888691
A13: 44396 | B13: 3239.3066 | C13: 15856.05 | D13: -0.00034868229 | E13: -0.004229661
A14: 44403 | B14: 3223.8623 | C14: 15763.05 | D14: -0.0047677907 | E14: -0.0058652692
A15: 44410 | B15: 3393.936 | C15: 16238.2 | D15: 0.052754651 | E15: 0.030143303
A16: 44417 | B16: 3370.9111 | C16: 16529.1 | D16: -0.0067841297 | E16: 0.017914511
A17: 44424 | B17: 3668.8689 | C17: 16450.5 | D17: 0.088390869 | E17: -0.0047552263
A18: 44431 | B18: 3711.8113 | C18: 16705.199 | D18: 0.011704529 | E18: 0.015482765
A19: 44438 | B19: 3883.8157 | C19: 17323.6 | D19: 0.046339747 | E19: 0.037018439
A20: 44445 | B20: 3833.5278 | C20: 17369.25 | D20: -0.012948051 | E20: 0.0026351562
A21: 44452 | B21: 3815.6824 | C21: 17585.15 | D21: -0.0046551009 | E21: 0.012430035
A22: 44459 | B22: 3807.2537 | C22: 17853.199 | D22: -0.0022089656 | E22: 0.015242908
... A263: 46146 | B263: 5520 | C263: 24176.15 | D263: -0.035976249 | E263: 0.0074424099
